Workbook

Sheet Dashboard
B2: Made for Doraemon
B4: Sample product (template) | G4: CURRENCY | H4: JPY
B5: 保湿 化粧水 · 36-month financial model · sales start Aug · built 2026-06-18 | H5: =IF(a_currency="USD",a_fx_jpy_per_usd,1) -> 1
B7: Input quality flags: cogs-benchmark, no-payback-within-36m — see Assumptions for what each means.
B9: Key indicators (live — follow the scenario switcher)
B11: 3Y EBITDA | D11: EBITDA MARGIN, YEAR 3 | F11: PAYBACK MONTH | H11: PEAK FUNDING NEED
B12: ='Investment and Cash'!C31 -> -3015200.2 | D12: =IF(SUM('PL Monthly'!AA17:AL17)=0,0,SUM('PL Monthly'!AA35:AL35)/SUM('PL Monthly'!AA17:AL17)) -> -0.20525088 | F12: ='Investment and Cash'!C29 -> n/a | H12: ='Investment and Cash'!C27 -> 3888349.2
B15: PEAK FUNDING (USD) | D15: REVENUE, YEAR 1 | F15: GROSS MARGIN (PRICE - FEES) | H15: NET CONTRIBUTION (M7-12)
B16: ='Investment and Cash'!C28 -> 25922.328 | D16: =SUM('PL Monthly'!C17:N17) -> 1793590.9 | F16: ='Investment and Cash'!C33 -> 0.77742857 | H16: ='Investment and Cash'!C34 -> 0.14786872
B20: Scenario comparison
B21: Scenario | C21: EBITDA Y1 | D21: EBITDA 3Y | E21: Margin Y3 | F21: Payback | G21: Peak funding | H21: Gross Margin | I21: Net Contribution
B22: pessimistic | C22: =-1480208.66589624/a_cur_div -> -1480208.7 | D22: =-4420816.04387649/a_cur_div -> -4420816 | E22: -0.66472998 | F22: n/a | G22: =5041311.05964144/a_cur_div -> 5041311.1 | H22: 0.74778571 | I22: -0.046687943
B23: base | C23: =-1249418.39162667/a_cur_div -> -1249418.4 | D23: =-3015200.21537217/a_cur_div -> -3015200.2 | E23: -0.20525088 | F23: n/a | G23: =3888349.22700065/a_cur_div -> 3888349.2 | H23: 0.77742857 | I23: 0.14786872
B24: optimistic | C24: =-834773.152993455/a_cur_div -> -834773.15 | D24: =-612662.522197003/a_cur_div -> -612662.52 | E24: 0.048312704 | F24: n/a | G24: =2246626.58450954/a_cur_div -> 2246626.6 | H24: 0.79719048 | I24: 0.27423983
B25: Static engine snapshot per scenario; the cards above and all P&L/Cash sheets are live and follow the Assumptions switcher.
B27: Key inputs (live)
B28: Selling price (active scenario) | D28: =a_act_asp_jpy/a_cur_div -> 3500
B29: Unit cost | D29: =a_unit_cogs_jpy/a_cur_div -> 1575
B30: Target market share | D30: =a_act_target_share -> 0.05
B31: Ad spend % (month 1) | D31: =a_act_tacos_y1_start -> 0.25
B32: Launch ad budget floor / mo | D32: =a_ppc_launch_monthly_min_jpy/a_cur_div -> 30000
B33: Launch costs (incl. contingency) | D33: =a_act_capex_total/a_cur_div -> 519200
B35: Model 9fcc27a6-4dce-47b4-81ae-8308eb866f32 · engine fm-7 · shipped on the base scenario · full inputs on the Assumptions sheet

Sheet Criteria
B2: Made for Doraemon
B4: Investment Criteria
B5: Live go / no-go check against the four financial gates. Follows the scenario switcher; the $ gates use the fixed USD memo rate. Green = met.
B7: =IF($C$18=4,"MEETS ALL 4 CRITERIA","NOT MET - "&(4-$C$18)&" OF 4 FAIL") -> NOT MET - 3 OF 4 FAIL
B10: ="Scenario: "&a_scenario&" | "&$C$18&" of 4 met" -> Scenario: base | 1 of 4 met
B12: Criterion | C12: Target | D12: This product | E12: Status
B13: Launch budget — peak cash need stays within budget | C13: max $20,000 | D13: ='Investment and Cash'!C28 -> 25922.328 | E13: =IF(D13<=20000,"PASS","FAIL") -> FAIL
B14: Cumulative revenue, first 6 sales months | C14: min $7,000 | D14: =(SUM('PL Monthly'!C12:H12))*a_cur_div/a_fx_jpy_per_usd -> 4083.3333 | E14: =IF(D14>=7000,"PASS","FAIL") -> FAIL
B15: Gross margin after Amazon fees (referral + FBA) | C15: min 40% | D15: ='Investment and Cash'!C33 -> 0.77742857 | E15: =IF(D15>=0.4,"PASS","FAIL") -> PASS
B16: Net contribution margin at steady state (month 7+) | C16: min 15% | D16: ='Investment and Cash'!C34 -> 0.14786872 | E16: =IF(D16>=0.15,"PASS","FAIL") -> FAIL
C18: =(D13<=20000)+(D14>=7000)+(D15>=0.4)+(D16>=0.15) -> 1
B20: Definitions — Revenue = gross sales (units x selling price, tax-inclusive). Gross margin = (Selling price - referral - FBA) / price. Net contribution margin = (Revenue - COGS - Amazon fees - PPC) / Revenue, at steady state (months 7-12). The $ gates are evaluated in USD at the memo rate regardless of the display currency. Flip the scenario on Assumptions to test each one.

Sheet Assumptions
B2: Made for Doraemon
B4: Assumptions
B5: Every input that drives the model — edit the purple cells, the whole workbook recalculates. Source / confidence / as-of show what each number rests on. 'Structural' rows need a rebuild by the agent.
B7: Volume & demand
B8: Assumption | C8: Value | D8: Unit | E8: What it is & what it drives | F8: Source | G8: Confidence | H8: As of | I8: Key (for the agent)
B9: Niche demand (units / year) | C9: 18000 | D9: units | E9: How many units the whole niche sells on Amazon JP per year. The base of every revenue number: your sales = this demand x your market share. | F9: enrichment.units_360d | G9: med | H9: 2026-06-11 | I9: units_360d
B10: Target market share | C10: 0.05 | D10: ratio | E10: The share of niche demand you aim to capture once ramped up. Drives units sold, and through them every revenue, cost and cash line. | F10: internal default — single new entrant | G10: low | H10: 2026-06-11 | I10: target_share
B11: Market-share cap | C11: 0.25 | D11: ratio | E11: A plausibility ceiling: even optimistic scenarios cannot assume more than this share of the niche. | F11: internal default — plausibility cap | G11: low | H11: 2026-06-11 | I11: share_cap
B12: Ramp-up (months) | C12: 9 | D12: months | E12: How many months it takes to grow from launch to the full target share. Shorter ramp = faster revenue but a bigger first inventory order. | F12: internal default — typical PL ramp | G12: low | H12: 2026-06-11 | I12: ramp_months
B13: Market growth, year 2 | C13: 0.21 | D13: ratio | E13: How much the whole niche grows in year 2 (from search-volume trend). Grows the market, not your share. | F13: niches.search_volume_growth_180d annualized, clamped | G13: low | H13: 2026-06-11 | I13: demand_growth_y2
B14: Market growth, year 3 | C14: 0.21 | D14: ratio | E14: Same as year 2, applied on top in year 3. | F14: niches.search_volume_growth_180d annualized, clamped | G14: low | H14: 2026-06-11 | I14: demand_growth_y3
B15: Launch month (1-12) | C15: 8 | D15: month | E15: The calendar month of the first sales month (M1). Anchors seasonality and the Oct-Dec storage-fee season; every month column shows its calendar month. | F15: build month + lead window (default) | G15: low | H15: 2026-06-11 | I15: launch_calendar_month
B17: Revenue
B18: Assumption | C18: Value | D18: Unit | E18: What it is & what it drives | F18: Source | G18: Confidence | H18: As of | I18: Key (for the agent)
B19: Consumption tax rate (sales) | C19: 0.1 | D19: ratio | E19: JCT inside the Amazon price (10%; 8% for food/beverage). Carved out of every sale: revenue you keep = price / (1 + rate). | F19: NTA standard rate; 8% food only via explicit user override | G19: high | H19: 2026-06-11 | I19: jct_rate_output
B20: Amazon Points | C20: 0.01 | D20: ratio | E20: Seller-funded points Amazon adds to JP listings by default (~1% of price). Reduces revenue. | F20: Amazon JP points default | G20: high | H20: 2026-06-11 | I20: points_rate
B21: Promo discounts — launch | C21: 0.08 | D21: ratio | E21: Coupons and deals as % of sales during the launch window (incl. their Amazon fees). Launch is promo-heavy to win the first reviews and rank. | F21: Axalpha JP coupon/deal fees 2025-06 | G21: low | H21: 2026-06-11 | I21: promo_rate_launch
B22: Launch window (months) | C22: 3 | D22: months | E22: How long the launch-level promo rate and the launch PPC budget floor apply. | F22: internal default | G22: low | H22: 2026-06-11 | I22: promo_launch_months
B23: Promo discounts — steady | C23: 0.02 | D23: ratio | E23: Ongoing coupons/deals as % of sales after the launch window. | F23: Axalpha JP coupon/deal fees 2025-06 | G23: low | H23: 2026-06-11 | I23: promo_rate_steady
B24: Promo fixed cost / month | C24: 0 | D24: jpy | E24: Flat monthly promo spend (e.g. recurring deal-day fees), if any. | F24: internal default | G24: low | H24: 2026-06-11 | I24: promo_fixed_jpy
B25: Return rate | C25: 0.02 | D25: ratio | E25: Share of orders customers return (JP rates are low, 1-7% by category). Reverses revenue; returned units are written off in full. | F25: niches.return_rate_360d | G25: med | H25: 2026-06-11 | I25: return_rate
B27: Product cost & supply
B28: Assumption | C28: Value | D28: Unit | E28: What it is & what it drives | F28: Source | G28: Confidence | H28: As of | I28: Key (for the agent)
B29: Unit cost (procurement) | C29: 1575 | D29: jpy | E29: What one unit costs to buy or manufacture in Japan, before tax. The single biggest profit driver. A wholesale benchmark until a supplier/OEM quote replaces it. | F29: ECのミカタ 掛け率 | G29: low | H29: 2026-06-11 | I29: unit_cogs_jpy
B30: Logistics to Amazon / unit | C30: 50 | D30: jpy | E30: Moving one unit from the supplier to the Amazon warehouse (prep + carrier). | F30: FBA partner carrier (Yamato) | G30: low | H30: 2026-06-11 | I30: logistics_jpy_per_unit
B31: Quality inspection / unit | C31: 0 | D31: jpy | E31: Acceptance testing per unit; usually 0 for wholesale, set it for OEM batches. | F31: internal default — set per OEM contract | G31: low | H31: 2026-06-11 | I31: inspection_jpy_per_unit
B32: Shrinkage & write-offs | C32: 0.01 | D32: ratio | E32: Goods lost or damaged in the supply chain, % of goods cost. | F32: Value Added Resource FBA reimbursement 2025 | G32: low | H32: 2026-06-11 | I32: shrinkage_rate
B33: Returns salvage | C33: 0 | D33: ratio | E33: Share of a returned unit's cost you recover by reselling it. 0 = every return is a full write-off (conservative). | F33: internal default (conservative) | G33: med | H33: 2026-06-11 | I33: return_salvage_rate
B34: Supplier tax-invoice credit | C34: 1 | D34: ratio | E34: 1.0 if the supplier issues a qualified invoice (their JCT is fully recoverable). 0.8/0.5 for non-registered suppliers — the lost share becomes product cost. | F34: NTA invoice system transitional credits | G34: med | H34: 2026-06-11 | I34: supplier_invoice_credit_rate
B35: Minimum order quantity | C35: 0 | D35: units | E35: The smallest batch the supplier accepts. If it exceeds what you need, cash gets locked in extra stock. | F35: no MOQ until a supplier quote provides one | G35: low | H35: 2026-06-11 | I35: moq_units
B36: Supplier prepayment | C36: 0.5 | D36: ratio | E36: Share of the order paid when ordering (rest on delivery). Higher prepay = more cash needed earlier. | F36: JP OEM convention 50% at order / 50% at delivery; set 0 for 掛け払い invoice terms | G36: low | H36: 2026-06-11 | I36: prepay_order_pct
B38: Product size & Amazon category — edit these
B39: Assumption | C39: Value | D39: Unit | E39: What it is & what it drives | F39: Source | G39: Confidence | H39: As of | I39: Key (for the agent)
B40: Package length (mm) | C40: 180 | D40: mm | E40: Longest side of the shipped package. Drives the FBA size tier and the storage volume — enter the real packed dimensions and the fees recompute. | F40: enrichment package dims | G40: high | H40: 2026-06-11 | I40: package_length_mm
B41: Package width (mm) | C41: 60 | D41: mm | E41: Second side of the shipped package. Used for the size tier and storage volume. | F41: enrichment package dims | G41: high | H41: 2026-06-11 | I41: package_width_mm
B42: Package height (mm) | C42: 60 | D42: mm | E42: Third side of the shipped package. Used for the size tier and storage volume. | F42: enrichment package dims | G42: high | H42: 2026-06-11 | I42: package_height_mm
B43: Package weight (g) | C43: 350 | D43: g | E43: Shipped weight including packaging. Together with the size it sets the FBA tier (each tier has a weight ceiling). | F43: enrichment package dims | G43: high | H43: 2026-06-11 | I43: package_weight_g
B44: Amazon fee category | C44: Beauty, health & personal care | D44: category | E44: ="Lists as "&INDEX('Fee Reference'!$C$34:$C$45,a_fee_cat_idx)&" on Amazon — pick the English category; it sets the referral rate." -> Lists as ビューティ・ヘルス・パーソナルケア on Amazon — pick the English category; it sets the referral rate. | F44: mapped from niche category_group (amazon_jp_referral.yaml) | G44: med | H44: 2026-06-11 | I44: amazon_fee_category
B46: Amazon fees — computed from size, category & price (do not edit)
B47: Assumption | C47: Value | D47: Unit | E47: What it is & what it drives | F47: Source | G47: Confidence | H47: As of | I47: Key (for the agent)
...

Sheet Fee Reference
B2: Made for Doraemon
B4: Fee Reference
B5: The Amazon Japan fee tables that drive the calculator on the Assumptions sheet — reference data, do not edit. Source: sell.amazon.co.jp/pricing, effective 2026-04-01 (referral verified 2026-06-18, FBA 2026-06-04). FBA fees tax-incl; referral tax-excl.
B7: FBA fulfilment fee by size tier (配送代行手数料, tax-incl ¥)
B8: Size tier | C8: Explicit? | D8: max L mm | E8: max W mm | F8: max H mm | G8: max girth cm | H8: max wt g | I8: fee ¥ | J8: fee ¥ (≤¥1,000) | K8: fits
B9: 小型 | C9: 1 | D9: 250 | E9: 180 | F9: 20 | G9: 0 | H9: 250 | I9: 288 | J9: 222 | K9: =IF(C9=1,(a_pkg_longest_mm<=D9)*(a_pkg_mid_mm<=E9)*(a_pkg_shortest_mm<=F9)*(a_package_weight_g<=H9),(a_pkg_girth_cm<=G9)*(a_package_weight_g<=H9)) -> 0
B10: 標準1 | C10: 1 | D10: 350 | E10: 300 | F10: 33 | G10: 0 | H10: 1000 | I10: 318 | J10: 252 | K10: =IF(C10=1,(a_pkg_longest_mm<=D10)*(a_pkg_mid_mm<=E10)*(a_pkg_shortest_mm<=F10)*(a_package_weight_g<=H10),(a_pkg_girth_cm<=G10)*(a_package_weight_g<=H10)) -> 0
B11: 標準2 | C11: 0 | D11: 0 | E11: 0 | F11: 0 | G11: 20 | H11: 2000 | I11: 410 | J11: 344 | K11: =IF(C11=1,(a_pkg_longest_mm<=D11)*(a_pkg_mid_mm<=E11)*(a_pkg_shortest_mm<=F11)*(a_package_weight_g<=H11),(a_pkg_girth_cm<=G11)*(a_package_weight_g<=H11)) -> 0
B12: 標準3 | C12: 0 | D12: 0 | E12: 0 | F12: 0 | G12: 30 | H12: 2000 | I12: 415 | J12: 358 | K12: =IF(C12=1,(a_pkg_longest_mm<=D12)*(a_pkg_mid_mm<=E12)*(a_pkg_shortest_mm<=F12)*(a_package_weight_g<=H12),(a_pkg_girth_cm<=G12)*(a_package_weight_g<=H12)) -> 1
B13: 標準4 | C13: 0 | D13: 0 | E13: 0 | F13: 0 | G13: 40 | H13: 2000 | I13: 420 | J13: 371 | K13: =IF(C13=1,(a_pkg_longest_mm<=D13)*(a_pkg_mid_mm<=E13)*(a_pkg_shortest_mm<=F13)*(a_package_weight_g<=H13),(a_pkg_girth_cm<=G13)*(a_package_weight_g<=H13)) -> 1
B14: 標準5 | C14: 0 | D14: 0 | E14: 0 | F14: 0 | G14: 50 | H14: 2000 | I14: 425 | J14: 379 | K14: =IF(C14=1,(a_pkg_longest_mm<=D14)*(a_pkg_mid_mm<=E14)*(a_pkg_shortest_mm<=F14)*(a_package_weight_g<=H14),(a_pkg_girth_cm<=G14)*(a_package_weight_g<=H14)) -> 1
B15: 標準6 | C15: 0 | D15: 0 | E15: 0 | F15: 0 | G15: 60 | H15: 2000 | I15: 430 | J15: 391 | K15: =IF(C15=1,(a_pkg_longest_mm<=D15)*(a_pkg_mid_mm<=E15)*(a_pkg_shortest_mm<=F15)*(a_package_weight_g<=H15),(a_pkg_girth_cm<=G15)*(a_package_weight_g<=H15)) -> 1
B16: 標準7 | C16: 0 | D16: 0 | E16: 0 | F16: 0 | G16: 80 | H16: 5000 | I16: 472 | J16: 427 | K16: =IF(C16=1,(a_pkg_longest_mm<=D16)*(a_pkg_mid_mm<=E16)*(a_pkg_shortest_mm<=F16)*(a_package_weight_g<=H16),(a_pkg_girth_cm<=G16)*(a_package_weight_g<=H16)) -> 1
B17: 標準8 | C17: 0 | D17: 0 | E17: 0 | F17: 0 | G17: 100 | H17: 9000 | I17: 532 | J17: 466 | K17: =IF(C17=1,(a_pkg_longest_mm<=D17)*(a_pkg_mid_mm<=E17)*(a_pkg_shortest_mm<=F17)*(a_package_weight_g<=H17),(a_pkg_girth_cm<=G17)*(a_package_weight_g<=H17)) -> 1
B18: 大型1 | C18: 0 | D18: 0 | E18: 0 | F18: 0 | G18: 60 | H18: 2000 | I18: 589 | J18: 523 | K18: =IF(C18=1,(a_pkg_longest_mm<=D18)*(a_pkg_mid_mm<=E18)*(a_pkg_shortest_mm<=F18)*(a_package_weight_g<=H18),(a_pkg_girth_cm<=G18)*(a_package_weight_g<=H18)) -> 1
B19: 大型2 | C19: 0 | D19: 0 | E19: 0 | F19: 0 | G19: 80 | H19: 5000 | I19: 624 | J19: 558 | K19: =IF(C19=1,(a_pkg_longest_mm<=D19)*(a_pkg_mid_mm<=E19)*(a_pkg_shortest_mm<=F19)*(a_package_weight_g<=H19),(a_pkg_girth_cm<=G19)*(a_package_weight_g<=H19)) -> 1
B20: 大型3 | C20: 0 | D20: 0 | E20: 0 | F20: 0 | G20: 100 | H20: 10000 | I20: 675 | J20: 609 | K20: =IF(C20=1,(a_pkg_longest_mm<=D20)*(a_pkg_mid_mm<=E20)*(a_pkg_shortest_mm<=F20)*(a_package_weight_g<=H20),(a_pkg_girth_cm<=G20)*(a_package_weight_g<=H20)) -> 1
... B29: 特大型4 | C29: 0 | D29: 0 | E29: 0 | F29: 0 | G29: 260 | H29: 50000 | I29: 5625 | J29: 5559 | K29: =IF(C29=1,(a_pkg_longest_mm<=D29)*(a_pkg_mid_mm<=E29)*(a_pkg_shortest_mm<=F29)*(a_package_weight_g<=H29),(a_pkg_girth_cm<=G29)*(a_package_weight_g<=H29)) -> 1
B30: 特大型5 | C30: 0 | D30: 0 | E30: 0 | F30: 0 | G30: 400 | H30: 50000 | I30: 13950 | J30: 13884 | K30: =1 -> 1
B32: Referral fee by category (販売手数料, tax-excluded %)
B33: Category (English) | C33: カテゴリー | D33: <=¥750 | E33: ¥750-1,500 | F33: >¥1,500
B34: Beauty, health & personal care | C34: ビューティ・ヘルス・パーソナルケア | D34: 0.05 | E34: 0.084 | F34: 0.104
B35: Drugstore | C35: ドラッグストア | D35: 0.05 | E35: 0.084 | F35: 0.104
B36: Food & beverage | C36: 食品・飲料 | D36: 0.05 | E36: 0.084 | F36: 0.104
B37: Baby & maternity | C37: ベビー・マタニティ | D37: 0.05 | E37: 0.084 | F37: 0.154
B38: Pet supplies | C38: ペット用品 | D38: 0.05 | E38: 0.084 | F38: 0.154
B39: Sports & outdoors | C39: スポーツ・アウトドア | D39: 0.05 | E39: 0.104 | F39: 0.104
B40: Home & kitchen | C40: ホーム・キッチン | D40: 0.05 | E40: 0.154 | F40: 0.154
B41: Home & kitchen appliances | C41: ホーム・キッチン家電 | D41: 0.05 | E41: 0.104 | F41: 0.104
B42: Toys & hobbies | C42: おもちゃ・ホビー | D42: 0.05 | E42: 0.104 | F42: 0.104
B43: Stationery & office | C43: 文房具・オフィス用品 | D43: 0.05 | E43: 0.154 | F43: 0.154
B44: Gardening | C44: ガーデニング・園芸用品 | D44: 0.05 | E44: 0.154 | F44: 0.154
B45: Everything else (default) | C45: その他のカテゴリー | D45: 0.05 | E45: 0.154 | F45: 0.154

Sheet PL Monthly
B2: Made for Doraemon | N2: ="Currency: "&a_currency&" · switch on the Dashboard" -> Currency: JPY · switch on the Dashboard
B4: P&L — 36 months
B5: Live formulas; costs negative; sales start Aug (launch month drives seasonality). Flip the scenario on the Assumptions sheet and everything recalculates.
B7: P&L line | C7: M1 · Aug | D7: M2 · Sep | E7: M3 · Oct | F7: M4 · Nov | G7: M5 · Dec | H7: M6 · Jan | I7: M7 · Feb | J7: M8 · Mar | K7: M9 · Apr | L7: M10 · May | M7: M11 · Jun | N7: M12 · Jul | O7: M13 · Aug | P7: M14 · Sep | Q7: M15 · Oct | R7: M16 · Nov | S7: M17 · Dec | T7: M18 · Jan | U7: M19 · Feb | V7: M20 · Mar | W7: M21 · Apr | X7: M22 · May | Y7: M23 · Jun | Z7: M24 · Jul | AA7: M25 · Aug | AB7: M26 · Sep | AC7: M27 · Oct | AD7: M28 · Nov | AE7: M29 · Dec | AF7: M30 · Jan | AG7: M31 · Feb | AH7: M32 · Mar | AI7: M33 · Apr | AJ7: M34 · May | AK7: M35 · Jun | AL7: M36 · Jul
B8: · demand (whole niche, units) | C8: =a_units_360d/12*INDEX(a_seasonality,8)*1 -> 1500 | D8: =a_units_360d/12*INDEX(a_seasonality,9)*1 -> 1500 | E8: =a_units_360d/12*INDEX(a_seasonality,10)*1 -> 1500 | F8: =a_units_360d/12*INDEX(a_seasonality,11)*1 -> 1500 | G8: =a_units_360d/12*INDEX(a_seasonality,12)*1 -> 1500 | H8: =a_units_360d/12*INDEX(a_seasonality,1)*1 -> 1500 | I8: =a_units_360d/12*INDEX(a_seasonality,2)*1 -> 1500 | J8: =a_units_360d/12*INDEX(a_seasonality,3)*1 -> 1500 | K8: =a_units_360d/12*INDEX(a_seasonality,4)*1 -> 1500 | L8: =a_units_360d/12*INDEX(a_seasonality,5)*1 -> 1500 | M8: =a_units_360d/12*INDEX(a_seasonality,6)*1 -> 1500 | N8: =a_units_360d/12*INDEX(a_seasonality,7)*1 -> 1500 | O8: =a_units_360d/12*INDEX(a_seasonality,8)*(1+a_demand_growth_y2) -> 1815 | P8: =a_units_360d/12*INDEX(a_seasonality,9)*(1+a_demand_growth_y2) -> 1815 | Q8: =a_units_360d/12*INDEX(a_seasonality,10)*(1+a_demand_growth_y2) -> 1815 | R8: =a_units_360d/12*INDEX(a_seasonality,11)*(1+a_demand_growth_y2) -> 1815 | S8: =a_units_360d/12*INDEX(a_seasonality,12)*(1+a_demand_growth_y2) -> 1815 | T8: =a_units_360d/12*INDEX(a_seasonality,1)*(1+a_demand_growth_y2) -> 1815 | U8: =a_units_360d/12*INDEX(a_seasonality,2)*(1+a_demand_growth_y2) -> 1815 | V8: =a_units_360d/12*INDEX(a_seasonality,3)*(1+a_demand_growth_y2) -> 1815 | W8: =a_units_360d/12*INDEX(a_seasonality,4)*(1+a_demand_growth_y2) -> 1815 | X8: =a_units_360d/12*INDEX(a_seasonality,5)*(1+a_demand_growth_y2) -> 1815 | Y8: =a_units_360d/12*INDEX(a_seasonality,6)*(1+a_demand_growth_y2) -> 1815 | Z8: =a_units_360d/12*INDEX(a_seasonality,7)*(1+a_demand_growth_y2) -> 1815 | AA8: =a_units_360d/12*INDEX(a_seasonality,8)*(1+a_demand_growth_y2)*(1+a_demand_growth_y3) -> 2196.15 | AB8: =a_units_360d/12*INDEX(a_seasonality,9)*(1+a_demand_growth_y2)*(1+a_demand_growth_y3) -> 2196.15 | AC8: =a_units_360d/12*INDEX(a_seasonality,10)*(1+a_demand_growth_y2)*(1+a_demand_growth_y3) -> 2196.15 | AD8: =a_units_360d/12*INDEX(a_seasonality,11)*(1+a_demand_growth_y2)*(1+a_demand_growth_y3) -> 2196.15 | AE8: =a_units_360d/12*INDEX(a_seasonality,12)*(1+a_demand_growth_y2)*(1+a_demand_growth_y3) -> 2196.15 | AF8: =a_units_360d/12*INDEX(a_seasonality,1)*(1+a_demand_growth_y2)*(1+a_demand_growth_y3) -> 2196.15 | AG8: =a_units_360d/12*INDEX(a_seasonality,2)*(1+a_demand_growth_y2)*(1+a_demand_growth_y3) -> 2196.15 | AH8: =a_units_360d/12*INDEX(a_seasonality,3)*(1+a_demand_growth_y2)*(1+a_demand_growth_y3) -> 2196.15 | AI8: =a_units_360d/12*INDEX(a_seasonality,4)*(1+a_demand_growth_y2)*(1+a_demand_growth_y3) -> 2196.15 | AJ8: =a_units_360d/12*INDEX(a_seasonality,5)*(1+a_demand_growth_y2)*(1+a_demand_growth_y3) -> 2196.15 | AK8: =a_units_360d/12*INDEX(a_seasonality,6)*(1+a_demand_growth_y2)*(1+a_demand_growth_y3) -> 2196.15 | AL8: =a_units_360d/12*INDEX(a_seasonality,7)*(1+a_demand_growth_y2)*(1+a_demand_growth_y3) -> 2196.15
B9: · your market share | C9: =MIN(a_act_target_share,a_share_cap)*MIN(1,1/a_ramp_months) -> 0.0055555556 | D9: =MIN(a_act_target_share,a_share_cap)*MIN(1,2/a_ramp_months) -> 0.011111111 | E9: =MIN(a_act_target_share,a_share_cap)*MIN(1,3/a_ramp_months) -> 0.016666667 | F9: =MIN(a_act_target_share,a_share_cap)*MIN(1,4/a_ramp_months) -> 0.022222222 | G9: =MIN(a_act_target_share,a_share_cap)*MIN(1,5/a_ramp_months) -> 0.027777778 | H9: =MIN(a_act_target_share,a_share_cap)*MIN(1,6/a_ramp_months) -> 0.033333333 | I9: =MIN(a_act_target_share,a_share_cap)*MIN(1,7/a_ramp_months) -> 0.038888889 | J9: =MIN(a_act_target_share,a_share_cap)*MIN(1,8/a_ramp_months) -> 0.044444444 | K9: =MIN(a_act_target_share,a_share_cap)*MIN(1,9/a_ramp_months) -> 0.05 | L9: =MIN(a_act_target_share,a_share_cap)*MIN(1,10/a_ramp_months) -> 0.05 | M9: =MIN(a_act_target_share,a_share_cap)*MIN(1,11/a_ramp_months) -> 0.05 | N9: =MIN(a_act_target_share,a_share_cap)*MIN(1,12/a_ramp_months) -> 0.05 | O9: =MIN(a_act_target_share,a_share_cap)*MIN(1,13/a_ramp_months) -> 0.05 | P9: =MIN(a_act_target_share,a_share_cap)*MIN(1,14/a_ramp_months) -> 0.05 | Q9: =MIN(a_act_target_share,a_share_cap)*MIN(1,15/a_ramp_months) -> 0.05 | R9: =MIN(a_act_target_share,a_share_cap)*MIN(1,16/a_ramp_months) -> 0.05 | S9: =MIN(a_act_target_share,a_share_cap)*MIN(1,17/a_ramp_months) -> 0.05 | T9: =MIN(a_act_target_share,a_share_cap)*MIN(1,18/a_ramp_months) -> 0.05 | U9: =MIN(a_act_target_share,a_share_cap)*MIN(1,19/a_ramp_months) -> 0.05 | V9: =MIN(a_act_target_share,a_share_cap)*MIN(1,20/a_ramp_months) -> 0.05 | W9: =MIN(a_act_target_share,a_share_cap)*MIN(1,21/a_ramp_months) -> 0.05 | X9: =MIN(a_act_target_share,a_share_cap)*MIN(1,22/a_ramp_months) -> 0.05 | Y9: =MIN(a_act_target_share,a_share_cap)*MIN(1,23/a_ramp_months) -> 0.05 | Z9: =MIN(a_act_target_share,a_share_cap)*MIN(1,24/a_ramp_months) -> 0.05 | AA9: =MIN(a_act_target_share,a_share_cap)*MIN(1,25/a_ramp_months) -> 0.05 | AB9: =MIN(a_act_target_share,a_share_cap)*MIN(1,26/a_ramp_months) -> 0.05 | AC9: =MIN(a_act_target_share,a_share_cap)*MIN(1,27/a_ramp_months) -> 0.05 | AD9: =MIN(a_act_target_share,a_share_cap)*MIN(1,28/a_ramp_months) -> 0.05 | AE9: =MIN(a_act_target_share,a_share_cap)*MIN(1,29/a_ramp_months) -> 0.05 | AF9: =MIN(a_act_target_share,a_share_cap)*MIN(1,30/a_ramp_months) -> 0.05 | AG9: =MIN(a_act_target_share,a_share_cap)*MIN(1,31/a_ramp_months) -> 0.05 | AH9: =MIN(a_act_target_share,a_share_cap)*MIN(1,32/a_ramp_months) -> 0.05 | AI9: =MIN(a_act_target_share,a_share_cap)*MIN(1,33/a_ramp_months) -> 0.05 | AJ9: =MIN(a_act_target_share,a_share_cap)*MIN(1,34/a_ramp_months) -> 0.05 | AK9: =MIN(a_act_target_share,a_share_cap)*MIN(1,35/a_ramp_months) -> 0.05 | AL9: =MIN(a_act_target_share,a_share_cap)*MIN(1,36/a_ramp_months) -> 0.05
B10: Units sold | C10: =C8*C9 -> 8.3333333 | D10: =D8*D9 -> 16.666667 | E10: =E8*E9 -> 25 | F10: =F8*F9 -> 33.333333 | G10: =G8*G9 -> 41.666667 | H10: =H8*H9 -> 50 | I10: =I8*I9 -> 58.333333 | J10: =J8*J9 -> 66.666667 | ... AL10: =AL8*AL9 -> 109.8075
B11: ASP (tax-incl) | C11: =a_act_asp_jpy/a_cur_div -> 3500 | D11: =a_act_asp_jpy/a_cur_div -> 3500 | E11: =a_act_asp_jpy/a_cur_div -> 3500 | F11: =a_act_asp_jpy/a_cur_div -> 3500 | G11: =a_act_asp_jpy/a_cur_div -> 3500 | H11: =a_act_asp_jpy/a_cur_div -> 3500 | I11: =a_act_asp_jpy/a_cur_div -> 3500 | J11: =a_act_asp_jpy/a_cur_div -> 3500 | ... AL11: =a_act_asp_jpy/a_cur_div -> 3500
B12: Gross sales | C12: =C10*C11 -> 29166.667 | D12: =D10*D11 -> 58333.333 | E12: =E10*E11 -> 87500 | F12: =F10*F11 -> 116666.67 | G12: =G10*G11 -> 145833.33 | H12: =H10*H11 -> 175000 | I12: =I10*I11 -> 204166.67 | J12: =J10*J11 -> 233333.33 | ... AL12: =AL10*AL11 -> 384326.25
B13: Output JCT | C13: =-C12*a_jct_rate_output/(1+a_jct_rate_output) -> -2651.5152 | D13: =-D12*a_jct_rate_output/(1+a_jct_rate_output) -> -5303.0303 | E13: =-E12*a_jct_rate_output/(1+a_jct_rate_output) -> -7954.5455 | F13: =-F12*a_jct_rate_output/(1+a_jct_rate_output) -> -10606.061 | G13: =-G12*a_jct_rate_output/(1+a_jct_rate_output) -> -13257.576 | H13: =-H12*a_jct_rate_output/(1+a_jct_rate_output) -> -15909.091 | I13: =-I12*a_jct_rate_output/(1+a_jct_rate_output) -> -18560.606 | J13: =-J12*a_jct_rate_output/(1+a_jct_rate_output) -> -21212.121 | ... AL13: =-AL12*a_jct_rate_output/(1+a_jct_rate_output) -> -34938.75
B14: Amazon Points | C14: =-C12*a_points_rate -> -291.66667 | D14: =-D12*a_points_rate -> -583.33333 | E14: =-E12*a_points_rate -> -875 | F14: =-F12*a_points_rate -> -1166.6667 | G14: =-G12*a_points_rate -> -1458.3333 | H14: =-H12*a_points_rate -> -1750 | I14: =-I12*a_points_rate -> -2041.6667 | J14: =-J12*a_points_rate -> -2333.3333 | ... AL14: =-AL12*a_points_rate -> -3843.2625
B15: Promotions & deals | C15: =-C12*IF(1<=a_promo_launch_months,a_promo_rate_launch,a_promo_rate_steady)-a_promo_fixed_jpy/a_cur_div -> -2333.3333 | D15: =-D12*IF(2<=a_promo_launch_months,a_promo_rate_launch,a_promo_rate_steady)-a_promo_fixed_jpy/a_cur_div -> -4666.6667 | E15: =-E12*IF(3<=a_promo_launch_months,a_promo_rate_launch,a_promo_rate_steady)-a_promo_fixed_jpy/a_cur_div -> -7000 | F15: =-F12*IF(4<=a_promo_launch_months,a_promo_rate_launch,a_promo_rate_steady)-a_promo_fixed_jpy/a_cur_div -> -2333.3333 | G15: =-G12*IF(5<=a_promo_launch_months,a_promo_rate_launch,a_promo_rate_steady)-a_promo_fixed_jpy/a_cur_div -> -2916.6667 | H15: =-H12*IF(6<=a_promo_launch_months,a_promo_rate_launch,a_promo_rate_steady)-a_promo_fixed_jpy/a_cur_div -> -3500 | I15: =-I12*IF(7<=a_promo_launch_months,a_promo_rate_launch,a_promo_rate_steady)-a_promo_fixed_jpy/a_cur_div -> -4083.3333 | J15: =-J12*IF(8<=a_promo_launch_months,a_promo_rate_launch,a_promo_rate_steady)-a_promo_fixed_jpy/a_cur_div -> -4666.6667 | K15: =-K12*IF(9<=a_promo_launch_months,a_promo_rate_launch,a_promo_rate_steady)-a_promo_fixed_jpy/a_cur_div -> -5250 | L15: =-L12*IF(10<=a_promo_launch_months,a_promo_rate_launch,a_promo_rate_steady)-a_promo_fixed_jpy/a_cur_div -> -5250 | M15: =-M12*IF(11<=a_promo_launch_months,a_promo_rate_launch,a_promo_rate_steady)-a_promo_fixed_jpy/a_cur_div -> -5250 | N15: =-N12*IF(12<=a_promo_launch_months,a_promo_rate_launch,a_promo_rate_steady)-a_promo_fixed_jpy/a_cur_div -> -5250 | O15: =-O12*IF(13<=a_promo_launch_months,a_promo_rate_launch,a_promo_rate_steady)-a_promo_fixed_jpy/a_cur_div -> -6352.5 | P15: =-P12*IF(14<=a_promo_launch_months,a_promo_rate_launch,a_promo_rate_steady)-a_promo_fixed_jpy/a_cur_div -> -6352.5 | Q15: =-Q12*IF(15<=a_promo_launch_months,a_promo_rate_launch,a_promo_rate_steady)-a_promo_fixed_jpy/a_cur_div -> -6352.5 | R15: =-R12*IF(16<=a_promo_launch_months,a_promo_rate_launch,a_promo_rate_steady)-a_promo_fixed_jpy/a_cur_div -> -6352.5 | S15: =-S12*IF(17<=a_promo_launch_months,a_promo_rate_launch,a_promo_rate_steady)-a_promo_fixed_jpy/a_cur_div -> -6352.5 | T15: =-T12*IF(18<=a_promo_launch_months,a_promo_rate_launch,a_promo_rate_steady)-a_promo_fixed_jpy/a_cur_div -> -6352.5 | U15: =-U12*IF(19<=a_promo_launch_months,a_promo_rate_launch,a_promo_rate_steady)-a_promo_fixed_jpy/a_cur_div -> -6352.5 | V15: =-V12*IF(20<=a_promo_launch_months,a_promo_rate_launch,a_promo_rate_steady)-a_promo_fixed_jpy/a_cur_div -> -6352.5 | W15: =-W12*IF(21<=a_promo_launch_months,a_promo_rate_launch,a_promo_rate_steady)-a_promo_fixed_jpy/a_cur_div -> -6352.5 | X15: =-X12*IF(22<=a_promo_launch_months,a_promo_rate_launch,a_promo_rate_steady)-a_promo_fixed_jpy/a_cur_div -> -6352.5 | Y15: =-Y12*IF(23<=a_promo_launch_months,a_promo_rate_launch,a_promo_rate_steady)-a_promo_fixed_jpy/a_cur_div -> -6352.5 | Z15: =-Z12*IF(24<=a_promo_launch_months,a_promo_rate_launch,a_promo_rate_steady)-a_promo_fixed_jpy/a_cur_div -> -6352.5 | AA15: =-AA12*IF(25<=a_promo_launch_months,a_promo_rate_launch,a_promo_rate_steady)-a_promo_fixed_jpy/a_cur_div -> -7686.525 | AB15: =-AB12*IF(26<=a_promo_launch_months,a_promo_rate_launch,a_promo_rate_steady)-a_promo_fixed_jpy/a_cur_div -> -7686.525 | AC15: =-AC12*IF(27<=a_promo_launch_months,a_promo_rate_launch,a_promo_rate_steady)-a_promo_fixed_jpy/a_cur_div -> -7686.525 | AD15: =-AD12*IF(28<=a_promo_launch_months,a_promo_rate_launch,a_promo_rate_steady)-a_promo_fixed_jpy/a_cur_div -> -7686.525 | AE15: =-AE12*IF(29<=a_promo_launch_months,a_promo_rate_launch,a_promo_rate_steady)-a_promo_fixed_jpy/a_cur_div -> -7686.525 | AF15: =-AF12*IF(30<=a_promo_launch_months,a_promo_rate_launch,a_promo_rate_steady)-a_promo_fixed_jpy/a_cur_div -> -7686.525 | AG15: =-AG12*IF(31<=a_promo_launch_months,a_promo_rate_launch,a_promo_rate_steady)-a_promo_fixed_jpy/a_cur_div -> -7686.525 | AH15: =-AH12*IF(32<=a_promo_launch_months,a_promo_rate_launch,a_promo_rate_steady)-a_promo_fixed_jpy/a_cur_div -> -7686.525 | AI15: =-AI12*IF(33<=a_promo_launch_months,a_promo_rate_launch,a_promo_rate_steady)-a_promo_fixed_jpy/a_cur_div -> -7686.525 | AJ15: =-AJ12*IF(34<=a_promo_launch_months,a_promo_rate_launch,a_promo_rate_steady)-a_promo_fixed_jpy/a_cur_div -> -7686.525 | AK15: =-AK12*IF(35<=a_promo_launch_months,a_promo_rate_launch,a_promo_rate_steady)-a_promo_fixed_jpy/a_cur_div -> -7686.525 | AL15: =-AL12*IF(36<=a_promo_launch_months,a_promo_rate_launch,a_promo_rate_steady)-a_promo_fixed_jpy/a_cur_div -> -7686.525
B16: Returns | C16: =-a_return_rate*C12 -> -583.33333 | D16: =-a_return_rate*D12 -> -1166.6667 | E16: =-a_return_rate*E12 -> -1750 | F16: =-a_return_rate*F12 -> -2333.3333 | G16: =-a_return_rate*G12 -> -2916.6667 | H16: =-a_return_rate*H12 -> -3500 | I16: =-a_return_rate*I12 -> -4083.3333 | J16: =-a_return_rate*J12 -> -4666.6667 | ... AL16: =-a_return_rate*AL12 -> -7686.525
B17: Net revenue | C17: =C12+C13+C14+C15+C16 -> 23306.818 | D17: =D12+D13+D14+D15+D16 -> 46613.636 | E17: =E12+E13+E14+E15+E16 -> 69920.455 | F17: =F12+F13+F14+F15+F16 -> 100227.27 | G17: =G12+G13+G14+G15+G16 -> 125284.09 | H17: =H12+H13+H14+H15+H16 -> 150340.91 | I17: =I12+I13+I14+I15+I16 -> 175397.73 | J17: =J12+J13+J14+J15+J16 -> 200454.55 | ... AL17: =AL12+AL13+AL14+AL15+AL16 -> 330171.19
B18: Unit procurement cost | C18: =-C10*a_act_cogs_pu/a_cur_div -> -13125 | D18: =-D10*a_act_cogs_pu/a_cur_div -> -26250 | E18: =-E10*a_act_cogs_pu/a_cur_div -> -39375 | F18: =-F10*a_act_cogs_pu/a_cur_div -> -52500 | G18: =-G10*a_act_cogs_pu/a_cur_div -> -65625 | H18: =-H10*a_act_cogs_pu/a_cur_div -> -78750 | I18: =-I10*a_act_cogs_pu/a_cur_div -> -91875 | J18: =-J10*a_act_cogs_pu/a_cur_div -> -105000 | ... AL18: =-AL10*a_act_cogs_pu/a_cur_div -> -172946.81
B19: Domestic logistics to FBA | C19: =-C10*a_logistics_jpy_per_unit/a_cur_div -> -416.66667 | D19: =-D10*a_logistics_jpy_per_unit/a_cur_div -> -833.33333 | E19: =-E10*a_logistics_jpy_per_unit/a_cur_div -> -1250 | F19: =-F10*a_logistics_jpy_per_unit/a_cur_div -> -1666.6667 | G19: =-G10*a_logistics_jpy_per_unit/a_cur_div -> -2083.3333 | H19: =-H10*a_logistics_jpy_per_unit/a_cur_div -> -2500 | I19: =-I10*a_logistics_jpy_per_unit/a_cur_div -> -2916.6667 | J19: =-J10*a_logistics_jpy_per_unit/a_cur_div -> -3333.3333 | ... AL19: =-AL10*a_logistics_jpy_per_unit/a_cur_div -> -5490.375
B20: Inspection / QC | C20: =-C10*a_inspection_jpy_per_unit/a_cur_div -> 0 | D20: =-D10*a_inspection_jpy_per_unit/a_cur_div -> 0 | E20: =-E10*a_inspection_jpy_per_unit/a_cur_div -> 0 | F20: =-F10*a_inspection_jpy_per_unit/a_cur_div -> 0 | G20: =-G10*a_inspection_jpy_per_unit/a_cur_div -> 0 | H20: =-H10*a_inspection_jpy_per_unit/a_cur_div -> 0 | I20: =-I10*a_inspection_jpy_per_unit/a_cur_div -> 0 | J20: =-J10*a_inspection_jpy_per_unit/a_cur_div -> 0 | ... AL20: =-AL10*a_inspection_jpy_per_unit/a_cur_div -> 0
B21: Shrinkage & write-offs | C21: =a_shrinkage_rate*(C18+C19+C20)+C10*a_return_rate*a_return_salvage_rate*a_act_basis_pu/a_cur_div -> -135.41667 | D21: =a_shrinkage_rate*(D18+D19+D20)+D10*a_return_rate*a_return_salvage_rate*a_act_basis_pu/a_cur_div -> -270.83333 | E21: =a_shrinkage_rate*(E18+E19+E20)+E10*a_return_rate*a_return_salvage_rate*a_act_basis_pu/a_cur_div -> -406.25 | F21: =a_shrinkage_rate*(F18+F19+F20)+F10*a_return_rate*a_return_salvage_rate*a_act_basis_pu/a_cur_div -> -541.66667 | G21: =a_shrinkage_rate*(G18+G19+G20)+G10*a_return_rate*a_return_salvage_rate*a_act_basis_pu/a_cur_div -> -677.08333 | H21: =a_shrinkage_rate*(H18+H19+H20)+H10*a_return_rate*a_return_salvage_rate*a_act_basis_pu/a_cur_div -> -812.5 | I21: =a_shrinkage_rate*(I18+I19+I20)+I10*a_return_rate*a_return_salvage_rate*a_act_basis_pu/a_cur_div -> -947.91667 | J21: =a_shrinkage_rate*(J18+J19+J20)+J10*a_return_rate*a_return_salvage_rate*a_act_basis_pu/a_cur_div -> -1083.3333 | ... AL21: =a_shrinkage_rate*(AL18+AL19+AL20)+AL10*a_return_rate*a_return_salvage_rate*a_act_basis_pu/a_cur_div -> -1784.3719
B22: Gross profit | C22: =C17+C18+C19+C20+C21 -> 9629.7348 | D22: =D17+D18+D19+D20+D21 -> 19259.47 | E22: =E17+E18+E19+E20+E21 -> 28889.205 | F22: =F17+F18+F19+F20+F21 -> 45518.939 | G22: =G17+G18+G19+G20+G21 -> 56898.674 | H22: =H17+H18+H19+H20+H21 -> 68278.409 | I22: =I17+I18+I19+I20+I21 -> 79658.144 | J22: =J17+J18+J19+J20+J21 -> 91037.879 | ... AL22: =AL17+AL18+AL19+AL20+AL21 -> 149949.63
B23: Referral fee | C23: =-C10*a_act_referral_pu/a_cur_div -> -3033.3333 | D23: =-D10*a_act_referral_pu/a_cur_div -> -6066.6667 | E23: =-E10*a_act_referral_pu/a_cur_div -> -9100 | F23: =-F10*a_act_referral_pu/a_cur_div -> -12133.333 | G23: =-G10*a_act_referral_pu/a_cur_div -> -15166.667 | H23: =-H10*a_act_referral_pu/a_cur_div -> -18200 | I23: =-I10*a_act_referral_pu/a_cur_div -> -21233.333 | J23: =-J10*a_act_referral_pu/a_cur_div -> -24266.667 | ... AL23: =-AL10*a_act_referral_pu/a_cur_div -> -39969.93
B24: FBA fulfillment | C24: =-C10*a_fba_fee_net/a_cur_div -> -3143.9394 | D24: =-D10*a_fba_fee_net/a_cur_div -> -6287.8788 | E24: =-E10*a_fba_fee_net/a_cur_div -> -9431.8182 | F24: =-F10*a_fba_fee_net/a_cur_div -> -12575.758 | G24: =-G10*a_fba_fee_net/a_cur_div -> -15719.697 | H24: =-H10*a_fba_fee_net/a_cur_div -> -18863.636 | I24: =-I10*a_fba_fee_net/a_cur_div -> -22007.576 | J24: =-J10*a_fba_fee_net/a_cur_div -> -25151.515 | ... AL24: =-AL10*a_fba_fee_net/a_cur_div -> -41427.375
B25: Storage | C25: =-(('Investment and Cash'!E8+'Investment and Cash'!E11)/2)*a_unit_vol_1000cm3*a_storage_rate_jan_sep/a_cur_div -> -264.708 | D25: =-(('Investment and Cash'!F8+'Investment and Cash'!F11)/2)*a_unit_vol_1000cm3*a_storage_rate_jan_sep/a_cur_div -> -222.912 | E25: =-(('Investment and Cash'!G8+'Investment and Cash'!G11)/2)*a_unit_vol_1000cm3*a_storage_rate_oct_dec/a_cur_div -> -272.349 | F25: =-(('Investment and Cash'!H8+'Investment and Cash'!H11)/2)*a_unit_vol_1000cm3*a_storage_rate_oct_dec/a_cur_div -> -346.626 | G25: =-(('Investment and Cash'!I8+'Investment and Cash'!I11)/2)*a_unit_vol_1000cm3*a_storage_rate_oct_dec/a_cur_div -> -420.903 | H25: =-(('Investment and Cash'!J8+'Investment and Cash'!J11)/2)*a_unit_vol_1000cm3*a_storage_rate_jan_sep/a_cur_div -> -278.64 | I25: =-(('Investment and Cash'!K8+'Investment and Cash'!K11)/2)*a_unit_vol_1000cm3*a_storage_rate_jan_sep/a_cur_div -> -320.436 | J25: =-(('Investment and Cash'!L8+'Investment and Cash'!L11)/2)*a_unit_vol_1000cm3*a_storage_rate_jan_sep/a_cur_div -> -362.232 | K25: =-(('Investment and Cash'!M8+'Investment and Cash'!M11)/2)*a_unit_vol_1000cm3*a_storage_rate_jan_sep/a_cur_div -> -376.164 | L25: =-(('Investment and Cash'!N8+'Investment and Cash'!N11)/2)*a_unit_vol_1000cm3*a_storage_rate_jan_sep/a_cur_div -> -376.164 | M25: =-(('Investment and Cash'!O8+'Investment and Cash'!O11)/2)*a_unit_vol_1000cm3*a_storage_rate_jan_sep/a_cur_div -> -376.164 | N25: =-(('Investment and Cash'!P8+'Investment and Cash'!P11)/2)*a_unit_vol_1000cm3*a_storage_rate_jan_sep/a_cur_div -> -428.82696 | O25: =-(('Investment and Cash'!Q8+'Investment and Cash'!Q11)/2)*a_unit_vol_1000cm3*a_storage_rate_jan_sep/a_cur_div -> -455.15844 | P25: =-(('Investment and Cash'!R8+'Investment and Cash'!R11)/2)*a_unit_vol_1000cm3*a_storage_rate_jan_sep/a_cur_div -> -455.15844 | Q25: =-(('Investment and Cash'!S8+'Investment and Cash'!S11)/2)*a_unit_vol_1000cm3*a_storage_rate_oct_dec/a_cur_div -> -808.87653 | R25: =-(('Investment and Cash'!T8+'Investment and Cash'!T11)/2)*a_unit_vol_1000cm3*a_storage_rate_oct_dec/a_cur_div -> -808.87653 | S25: =-(('Investment and Cash'!U8+'Investment and Cash'!U11)/2)*a_unit_vol_1000cm3*a_storage_rate_oct_dec/a_cur_div -> -808.87653 | T25: =-(('Investment and Cash'!V8+'Investment and Cash'!V11)/2)*a_unit_vol_1000cm3*a_storage_rate_jan_sep/a_cur_div -> -455.15844 | U25: =-(('Investment and Cash'!W8+'Investment and Cash'!W11)/2)*a_unit_vol_1000cm3*a_storage_rate_jan_sep/a_cur_div -> -455.15844 | V25: =-(('Investment and Cash'!X8+'Investment and Cash'!X11)/2)*a_unit_vol_1000cm3*a_storage_rate_jan_sep/a_cur_div -> -455.15844 | W25: =-(('Investment and Cash'!Y8+'Investment and Cash'!Y11)/2)*a_unit_vol_1000cm3*a_storage_rate_jan_sep/a_cur_div -> -455.15844 | X25: =-(('Investment and Cash'!Z8+'Investment and Cash'!Z11)/2)*a_unit_vol_1000cm3*a_storage_rate_jan_sep/a_cur_div -> -455.15844 | Y25: =-(('Investment and Cash'!AA8+'Investment and Cash'!AA11)/2)*a_unit_vol_1000cm3*a_storage_rate_jan_sep/a_cur_div -> -455.15844 | Z25: =-(('Investment and Cash'!AB8+'Investment and Cash'!AB11)/2)*a_unit_vol_1000cm3*a_storage_rate_jan_sep/a_cur_div -> -518.88062 | AA25: =-(('Investment and Cash'!AC8+'Investment and Cash'!AC11)/2)*a_unit_vol_1000cm3*a_storage_rate_jan_sep/a_cur_div -> -550.74171 | AB25: =-(('Investment and Cash'!AD8+'Investment and Cash'!AD11)/2)*a_unit_vol_1000cm3*a_storage_rate_jan_sep/a_cur_div -> -550.74171 | AC25: =-(('Investment and Cash'!AE8+'Investment and Cash'!AE11)/2)*a_unit_vol_1000cm3*a_storage_rate_oct_dec/a_cur_div -> -978.7406 | AD25: =-(('Investment and Cash'!AF8+'Investment and Cash'!AF11)/2)*a_unit_vol_1000cm3*a_storage_rate_oct_dec/a_cur_div -> -978.7406 | AE25: =-(('Investment and Cash'!AG8+'Investment and Cash'!AG11)/2)*a_unit_vol_1000cm3*a_storage_rate_oct_dec/a_cur_div -> -978.7406 | AF25: =-(('Investment and Cash'!AH8+'Investment and Cash'!AH11)/2)*a_unit_vol_1000cm3*a_storage_rate_jan_sep/a_cur_div -> -550.74171 | AG25: =-(('Investment and Cash'!AI8+'Investment and Cash'!AI11)/2)*a_unit_vol_1000cm3*a_storage_rate_jan_sep/a_cur_div -> -550.74171 | AH25: =-(('Investment and Cash'!AJ8+'Investment and Cash'!AJ11)/2)*a_unit_vol_1000cm3*a_storage_rate_jan_sep/a_cur_div -> -550.74171 | AI25: =-(('Investment and Cash'!AK8+'Investment and Cash'!AK11)/2)*a_unit_vol_1000cm3*a_storage_rate_jan_sep/a_cur_div -> -550.74171 | AJ25: =-(('Investment and Cash'!AL8+'Investment and Cash'!AL11)/2)*a_unit_vol_1000cm3*a_storage_rate_jan_sep/a_cur_div -> -550.74171 | AK25: =-(('Investment and Cash'!AM8+'Investment and Cash'!AM11)/2)*a_unit_vol_1000cm3*a_storage_rate_jan_sep/a_cur_div -> -550.74171 | AL25: =-(('Investment and Cash'!AN8+'Investment and Cash'!AN11)/2)*a_unit_vol_1000cm3*a_storage_rate_jan_sep/a_cur_div -> -183.58057
B26: Long-term storage | C26: =INDEX('PL Monthly'!C41:C43,MATCH(a_scenario,a_scn_names,0))/a_cur_div -> 0 | D26: =INDEX('PL Monthly'!D41:D43,MATCH(a_scenario,a_scn_names,0))/a_cur_div -> 0 | E26: =INDEX('PL Monthly'!E41:E43,MATCH(a_scenario,a_scn_names,0))/a_cur_div -> 0 | F26: =INDEX('PL Monthly'!F41:F43,MATCH(a_scenario,a_scn_names,0))/a_cur_div -> 0 | G26: =INDEX('PL Monthly'!G41:G43,MATCH(a_scenario,a_scn_names,0))/a_cur_div -> 0 | H26: =INDEX('PL Monthly'!H41:H43,MATCH(a_scenario,a_scn_names,0))/a_cur_div -> 0 | I26: =INDEX('PL Monthly'!I41:I43,MATCH(a_scenario,a_scn_names,0))/a_cur_div -> 0 | J26: =INDEX('PL Monthly'!J41:J43,MATCH(a_scenario,a_scn_names,0))/a_cur_div -> 0 | ... AL26: =INDEX('PL Monthly'!AL41:AL43,MATCH(a_scenario,a_scn_names,0))/a_cur_div -> 0
B27: Referral refund on returns | C27: =C10*a_return_rate*(a_act_referral_pu-a_act_refund_admin_pu)/a_cur_div -> 48.533333 | D27: =D10*a_return_rate*(a_act_referral_pu-a_act_refund_admin_pu)/a_cur_div -> 97.066667 | E27: =E10*a_return_rate*(a_act_referral_pu-a_act_refund_admin_pu)/a_cur_div -> 145.6 | F27: =F10*a_return_rate*(a_act_referral_pu-a_act_refund_admin_pu)/a_cur_div -> 194.13333 | G27: =G10*a_return_rate*(a_act_referral_pu-a_act_refund_admin_pu)/a_cur_div -> 242.66667 | H27: =H10*a_return_rate*(a_act_referral_pu-a_act_refund_admin_pu)/a_cur_div -> 291.2 | I27: =I10*a_return_rate*(a_act_referral_pu-a_act_refund_admin_pu)/a_cur_div -> 339.73333 | J27: =J10*a_return_rate*(a_act_referral_pu-a_act_refund_admin_pu)/a_cur_div -> 388.26667 | ... AL27: =AL10*a_return_rate*(a_act_referral_pu-a_act_refund_admin_pu)/a_cur_div -> 639.51888
B28: Contribution margin | C28: =C22+C23+C24+C25+C26+C27 -> 3236.2875 | D28: =D22+D23+D24+D25+D26+D27 -> 6779.0789 | E28: =E22+E23+E24+E25+E26+E27 -> 10230.637 | F28: =F22+F23+F24+F25+F26+F27 -> 20657.356 | G28: =G22+G23+G24+G25+G26+G27 -> 25834.074 | H28: =H22+H23+H24+H25+H26+H27 -> 31227.333 | I28: =I22+I23+I24+I25+I26+I27 -> 36436.532 | J28: =J22+J23+J24+J25+J26+J27 -> 41645.732 | ... AL28: =AL22+AL23+AL24+AL25+AL26+AL27 -> 69008.261
B29: PPC advertising | C29: =-MAX(C12*MAX(0,a_act_tacos_y1_start+(a_act_tacos_y1_end-a_act_tacos_y1_start)*(1-1)/11),a_ppc_launch_monthly_min_jpy/a_cur_div) -> -30000 | D29: =-MAX(D12*MAX(0,a_act_tacos_y1_start+(a_act_tacos_y1_end-a_act_tacos_y1_start)*(2-1)/11),a_ppc_launch_monthly_min_jpy/a_cur_div) -> -30000 | E29: =-MAX(E12*MAX(0,a_act_tacos_y1_start+(a_act_tacos_y1_end-a_act_tacos_y1_start)*(3-1)/11),a_ppc_launch_monthly_min_jpy/a_cur_div) -> -30000 | F29: =-F12*MAX(0,a_act_tacos_y1_start+(a_act_tacos_y1_end-a_act_tacos_y1_start)*(4-1)/11) -> -25984.848 | G29: =-G12*MAX(0,a_act_tacos_y1_start+(a_act_tacos_y1_end-a_act_tacos_y1_start)*(5-1)/11) -> -31155.303 | H29: =-H12*MAX(0,a_act_tacos_y1_start+(a_act_tacos_y1_end-a_act_tacos_y1_start)*(6-1)/11) -> -35795.455 | I29: =-I12*MAX(0,a_act_tacos_y1_start+(a_act_tacos_y1_end-a_act_tacos_y1_start)*(7-1)/11) -> -39905.303 | J29: =-J12*MAX(0,a_act_tacos_y1_start+(a_act_tacos_y1_end-a_act_tacos_y1_start)*(8-1)/11) -> -43484.848 | K29: =-K12*MAX(0,a_act_tacos_y1_start+(a_act_tacos_y1_end-a_act_tacos_y1_start)*(9-1)/11) -> -46534.091 | L29: =-L12*MAX(0,a_act_tacos_y1_start+(a_act_tacos_y1_end-a_act_tacos_y1_start)*(10-1)/11) -> -44147.727 | M29: =-M12*MAX(0,a_act_tacos_y1_start+(a_act_tacos_y1_end-a_act_tacos_y1_start)*(11-1)/11) -> -41761.364 | N29: =-N12*MAX(0,a_act_tacos_y1_start+(a_act_tacos_y1_end-a_act_tacos_y1_start)*(12-1)/11) -> -39375 | O29: =-O12*a_act_tacos_y2 -> -38115 | P29: =-P12*a_act_tacos_y2 -> -38115 | Q29: =-Q12*a_act_tacos_y2 -> -38115 | R29: =-R12*a_act_tacos_y2 -> -38115 | S29: =-S12*a_act_tacos_y2 -> -38115 | T29: =-T12*a_act_tacos_y2 -> -38115 | U29: =-U12*a_act_tacos_y2 -> -38115 | V29: =-V12*a_act_tacos_y2 -> -38115 | ... Z29: =-Z12*a_act_tacos_y2 -> -38115 | AA29: =-AA12*a_act_tacos_y3 -> -38432.625 | AB29: =-AB12*a_act_tacos_y3 -> -38432.625 | AC29: =-AC12*a_act_tacos_y3 -> -38432.625 | AD29: =-AD12*a_act_tacos_y3 -> -38432.625 | AE29: =-AE12*a_act_tacos_y3 -> -38432.625 | AF29: =-AF12*a_act_tacos_y3 -> -38432.625 | AG29: =-AG12*a_act_tacos_y3 -> -38432.625 | AH29: =-AH12*a_act_tacos_y3 -> -38432.625 | ... AL29: =-AL12*a_act_tacos_y3 -> -38432.625
B30: Content & creative | C30: =-a_content_monthly_jpy/a_cur_div -> -20000 | D30: =-a_content_monthly_jpy/a_cur_div -> -20000 | E30: =-a_content_monthly_jpy/a_cur_div -> -20000 | F30: =-a_content_monthly_jpy/a_cur_div -> -20000 | G30: =-a_content_monthly_jpy/a_cur_div -> -20000 | H30: =-a_content_monthly_jpy/a_cur_div -> -20000 | I30: =-a_content_monthly_jpy/a_cur_div -> -20000 | J30: =-a_content_monthly_jpy/a_cur_div -> -20000 | ... AL30: =-a_content_monthly_jpy/a_cur_div -> -20000
B31: Influencers & affiliates | C31: =-a_influencer_monthly_jpy/a_cur_div -> 0 | D31: =-a_influencer_monthly_jpy/a_cur_div -> 0 | E31: =-a_influencer_monthly_jpy/a_cur_div -> 0 | F31: =-a_influencer_monthly_jpy/a_cur_div -> 0 | G31: =-a_influencer_monthly_jpy/a_cur_div -> 0 | H31: =-a_influencer_monthly_jpy/a_cur_div -> 0 | I31: =-a_influencer_monthly_jpy/a_cur_div -> 0 | J31: =-a_influencer_monthly_jpy/a_cur_div -> 0 | ... AL31: =-a_influencer_monthly_jpy/a_cur_div -> 0
B32: Subscription | C32: =-a_subscription_monthly_jpy/a_products_sharing_overhead/a_cur_div -> -4900 | D32: =-a_subscription_monthly_jpy/a_products_sharing_overhead/a_cur_div -> -4900 | E32: =-a_subscription_monthly_jpy/a_products_sharing_overhead/a_cur_div -> -4900 | F32: =-a_subscription_monthly_jpy/a_products_sharing_overhead/a_cur_div -> -4900 | G32: =-a_subscription_monthly_jpy/a_products_sharing_overhead/a_cur_div -> -4900 | H32: =-a_subscription_monthly_jpy/a_products_sharing_overhead/a_cur_div -> -4900 | I32: =-a_subscription_monthly_jpy/a_products_sharing_overhead/a_cur_div -> -4900 | J32: =-a_subscription_monthly_jpy/a_products_sharing_overhead/a_cur_div -> -4900 | ... AL32: =-a_subscription_monthly_jpy/a_products_sharing_overhead/a_cur_div -> -4900
B33: Insurance (PL) | C33: =-a_insurance_monthly_jpy/a_cur_div -> -3000 | D33: =-a_insurance_monthly_jpy/a_cur_div -> -3000 | E33: =-a_insurance_monthly_jpy/a_cur_div -> -3000 | F33: =-a_insurance_monthly_jpy/a_cur_div -> -3000 | G33: =-a_insurance_monthly_jpy/a_cur_div -> -3000 | H33: =-a_insurance_monthly_jpy/a_cur_div -> -3000 | I33: =-a_insurance_monthly_jpy/a_cur_div -> -3000 | J33: =-a_insurance_monthly_jpy/a_cur_div -> -3000 | ... AL33: =-a_insurance_monthly_jpy/a_cur_div -> -3000
B34: Management fee & admin | C34: =-IF(1<a_mgmt_fee_start_month,0,a_mgmt_fee_fixed_jpy*(1+a_mgmt_fee_escalation_pct)^0/a_cur_div)/a_products_sharing_overhead -> -70000 | D34: =-IF(2<a_mgmt_fee_start_month,0,a_mgmt_fee_fixed_jpy*(1+a_mgmt_fee_escalation_pct)^0/a_cur_div)/a_products_sharing_overhead -> -70000 | E34: =-IF(3<a_mgmt_fee_start_month,0,a_mgmt_fee_fixed_jpy*(1+a_mgmt_fee_escalation_pct)^0/a_cur_div)/a_products_sharing_overhead -> -70000 | F34: =-IF(4<a_mgmt_fee_start_month,0,a_mgmt_fee_fixed_jpy*(1+a_mgmt_fee_escalation_pct)^0/a_cur_div)/a_products_sharing_overhead -> -70000 | G34: =-IF(5<a_mgmt_fee_start_month,0,a_mgmt_fee_fixed_jpy*(1+a_mgmt_fee_escalation_pct)^0/a_cur_div)/a_products_sharing_overhead -> -70000 | H34: =-IF(6<a_mgmt_fee_start_month,0,a_mgmt_fee_fixed_jpy*(1+a_mgmt_fee_escalation_pct)^0/a_cur_div)/a_products_sharing_overhead -> -70000 | I34: =-IF(7<a_mgmt_fee_start_month,0,a_mgmt_fee_fixed_jpy*(1+a_mgmt_fee_escalation_pct)^0/a_cur_div)/a_products_sharing_overhead -> -70000 | J34: =-IF(8<a_mgmt_fee_start_month,0,a_mgmt_fee_fixed_jpy*(1+a_mgmt_fee_escalation_pct)^0/a_cur_div)/a_products_sharing_overhead -> -70000 | K34: =-IF(9<a_mgmt_fee_start_month,0,a_mgmt_fee_fixed_jpy*(1+a_mgmt_fee_escalation_pct)^0/a_cur_div)/a_products_sharing_overhead -> -70000 | L34: =-IF(10<a_mgmt_fee_start_month,0,a_mgmt_fee_fixed_jpy*(1+a_mgmt_fee_escalation_pct)^0/a_cur_div)/a_products_sharing_overhead -> -70000 | M34: =-IF(11<a_mgmt_fee_start_month,0,a_mgmt_fee_fixed_jpy*(1+a_mgmt_fee_escalation_pct)^0/a_cur_div)/a_products_sharing_overhead -> -70000 | N34: =-IF(12<a_mgmt_fee_start_month,0,a_mgmt_fee_fixed_jpy*(1+a_mgmt_fee_escalation_pct)^0/a_cur_div)/a_products_sharing_overhead -> -70000 | O34: =-IF(13<a_mgmt_fee_start_month,0,a_mgmt_fee_fixed_jpy*(1+a_mgmt_fee_escalation_pct)^1/a_cur_div)/a_products_sharing_overhead -> -70000 | P34: =-IF(14<a_mgmt_fee_start_month,0,a_mgmt_fee_fixed_jpy*(1+a_mgmt_fee_escalation_pct)^1/a_cur_div)/a_products_sharing_overhead -> -70000 | Q34: =-IF(15<a_mgmt_fee_start_month,0,a_mgmt_fee_fixed_jpy*(1+a_mgmt_fee_escalation_pct)^1/a_cur_div)/a_products_sharing_overhead -> -70000 | R34: =-IF(16<a_mgmt_fee_start_month,0,a_mgmt_fee_fixed_jpy*(1+a_mgmt_fee_escalation_pct)^1/a_cur_div)/a_products_sharing_overhead -> -70000 | S34: =-IF(17<a_mgmt_fee_start_month,0,a_mgmt_fee_fixed_jpy*(1+a_mgmt_fee_escalation_pct)^1/a_cur_div)/a_products_sharing_overhead -> -70000 | T34: =-IF(18<a_mgmt_fee_start_month,0,a_mgmt_fee_fixed_jpy*(1+a_mgmt_fee_escalation_pct)^1/a_cur_div)/a_products_sharing_overhead -> -70000 | U34: =-IF(19<a_mgmt_fee_start_month,0,a_mgmt_fee_fixed_jpy*(1+a_mgmt_fee_escalation_pct)^1/a_cur_div)/a_products_sharing_overhead -> -70000 | V34: =-IF(20<a_mgmt_fee_start_month,0,a_mgmt_fee_fixed_jpy*(1+a_mgmt_fee_escalation_pct)^1/a_cur_div)/a_products_sharing_overhead -> -70000 | W34: =-IF(21<a_mgmt_fee_start_month,0,a_mgmt_fee_fixed_jpy*(1+a_mgmt_fee_escalation_pct)^1/a_cur_div)/a_products_sharing_overhead -> -70000 | X34: =-IF(22<a_mgmt_fee_start_month,0,a_mgmt_fee_fixed_jpy*(1+a_mgmt_fee_escalation_pct)^1/a_cur_div)/a_products_sharing_overhead -> -70000 | Y34: =-IF(23<a_mgmt_fee_start_month,0,a_mgmt_fee_fixed_jpy*(1+a_mgmt_fee_escalation_pct)^1/a_cur_div)/a_products_sharing_overhead -> -70000 | Z34: =-IF(24<a_mgmt_fee_start_month,0,a_mgmt_fee_fixed_jpy*(1+a_mgmt_fee_escalation_pct)^1/a_cur_div)/a_products_sharing_overhead -> -70000 | AA34: =-IF(25<a_mgmt_fee_start_month,0,a_mgmt_fee_fixed_jpy*(1+a_mgmt_fee_escalation_pct)^2/a_cur_div)/a_products_sharing_overhead -> -70000 | AB34: =-IF(26<a_mgmt_fee_start_month,0,a_mgmt_fee_fixed_jpy*(1+a_mgmt_fee_escalation_pct)^2/a_cur_div)/a_products_sharing_overhead -> -70000 | AC34: =-IF(27<a_mgmt_fee_start_month,0,a_mgmt_fee_fixed_jpy*(1+a_mgmt_fee_escalation_pct)^2/a_cur_div)/a_products_sharing_overhead -> -70000 | AD34: =-IF(28<a_mgmt_fee_start_month,0,a_mgmt_fee_fixed_jpy*(1+a_mgmt_fee_escalation_pct)^2/a_cur_div)/a_products_sharing_overhead -> -70000 | AE34: =-IF(29<a_mgmt_fee_start_month,0,a_mgmt_fee_fixed_jpy*(1+a_mgmt_fee_escalation_pct)^2/a_cur_div)/a_products_sharing_overhead -> -70000 | AF34: =-IF(30<a_mgmt_fee_start_month,0,a_mgmt_fee_fixed_jpy*(1+a_mgmt_fee_escalation_pct)^2/a_cur_div)/a_products_sharing_overhead -> -70000 | AG34: =-IF(31<a_mgmt_fee_start_month,0,a_mgmt_fee_fixed_jpy*(1+a_mgmt_fee_escalation_pct)^2/a_cur_div)/a_products_sharing_overhead -> -70000 | AH34: =-IF(32<a_mgmt_fee_start_month,0,a_mgmt_fee_fixed_jpy*(1+a_mgmt_fee_escalation_pct)^2/a_cur_div)/a_products_sharing_overhead -> -70000 | AI34: =-IF(33<a_mgmt_fee_start_month,0,a_mgmt_fee_fixed_jpy*(1+a_mgmt_fee_escalation_pct)^2/a_cur_div)/a_products_sharing_overhead -> -70000 | AJ34: =-IF(34<a_mgmt_fee_start_month,0,a_mgmt_fee_fixed_jpy*(1+a_mgmt_fee_escalation_pct)^2/a_cur_div)/a_products_sharing_overhead -> -70000 | AK34: =-IF(35<a_mgmt_fee_start_month,0,a_mgmt_fee_fixed_jpy*(1+a_mgmt_fee_escalation_pct)^2/a_cur_div)/a_products_sharing_overhead -> -70000 | AL34: =-IF(36<a_mgmt_fee_start_month,0,a_mgmt_fee_fixed_jpy*(1+a_mgmt_fee_escalation_pct)^2/a_cur_div)/a_products_sharing_overhead -> -70000
B35: EBITDA | C35: =C28+C29+C30+C31+C32+C33+C34 -> -124663.71 | D35: =D28+D29+D30+D31+D32+D33+D34 -> -121120.92 | E35: =E28+E29+E30+E31+E32+E33+E34 -> -117669.36 | F35: =F28+F29+F30+F31+F32+F33+F34 -> -103227.49 | G35: =G28+G29+G30+G31+G32+G33+G34 -> -103221.23 | H35: =H28+H29+H30+H31+H32+H33+H34 -> -102468.12 | I35: =I28+I29+I30+I31+I32+I33+I34 -> -101368.77 | J35: =J28+J29+J30+J31+J32+J33+J34 -> -99739.117 | ... AL35: =AL28+AL29+AL30+AL31+AL32+AL33+AL34 -> -67324.364
B36: EBITDA margin % | C36: =IF(C17=0,0,C35/C17) -> -5.3488087 | D36: =IF(D17=0,0,D35/D17) -> -2.598401 | E36: =IF(E17=0,0,E35/E17) -> -1.6829033 | F36: =IF(F17=0,0,F35/F17) -> -1.0299342 | G36: =IF(G17=0,0,G35/G17) -> -0.82389734 | H36: =IF(H17=0,0,H35/H17) -> -0.68157179 | I36: =IF(I17=0,0,I35/I17) -> -0.57793663 | J36: =IF(J17=0,0,J35/J17) -> -0.49756476 | ... AL36: =IF(AL17=0,0,AL35/AL17) -> -0.20390745
B37: Operating metrics
B38: Advertising ROAS | C38: =IF(C29=0,0,-C12/C29) -> 0.97222222 | D38: =IF(D29=0,0,-D12/D29) -> 1.9444444 | E38: =IF(E29=0,0,-E12/E29) -> 2.9166667 | F38: =IF(F29=0,0,-F12/F29) -> 4.4897959 | G38: =IF(G29=0,0,-G12/G29) -> 4.6808511 | H38: =IF(H29=0,0,-H12/H29) -> 4.8888889 | I38: =IF(I29=0,0,-I12/I29) -> 5.1162791 | J38: =IF(J29=0,0,-J12/J29) -> 5.3658537 | ... AL38: =IF(AL29=0,0,-AL12/AL29) -> 10
B39: Inventory turnover | C39: =IF(('Investment and Cash'!E8+'Investment and Cash'!E11)=0,0,24*C10/('Investment and Cash'!E8+'Investment and Cash'!E11)) -> 1.2631579 | D39: =IF(('Investment and Cash'!F8+'Investment and Cash'!F11)=0,0,24*D10/('Investment and Cash'!F8+'Investment and Cash'!F11)) -> 3 | E39: =IF(('Investment and Cash'!G8+'Investment and Cash'!G11)=0,0,24*E10/('Investment and Cash'!G8+'Investment and Cash'!G11)) -> 6.5454545 | F39: =IF(('Investment and Cash'!H8+'Investment and Cash'!H11)=0,0,24*F10/('Investment and Cash'!H8+'Investment and Cash'!H11)) -> 6.8571429 | G39: =IF(('Investment and Cash'!I8+'Investment and Cash'!I11)=0,0,24*G10/('Investment and Cash'!I8+'Investment and Cash'!I11)) -> 7.0588235 | H39: =IF(('Investment and Cash'!J8+'Investment and Cash'!J11)=0,0,24*H10/('Investment and Cash'!J8+'Investment and Cash'!J11)) -> 7.2 | I39: =IF(('Investment and Cash'!K8+'Investment and Cash'!K11)=0,0,24*I10/('Investment and Cash'!K8+'Investment and Cash'!K11)) -> 7.3043478 | J39: =IF(('Investment and Cash'!L8+'Investment and Cash'!L11)=0,0,24*J10/('Investment and Cash'!L8+'Investment and Cash'!L11)) -> 7.3846154 | ... AL39: =IF(('Investment and Cash'!AN8+'Investment and Cash'!AN11)=0,0,24*AL10/('Investment and Cash'!AN8+'Investment and Cash'!AN11)) -> 24
B40: Return rate | C40: =IF(C12=0,0,-C16/C12) -> 0.02 | D40: =IF(D12=0,0,-D16/D12) -> 0.02 | E40: =IF(E12=0,0,-E16/E12) -> 0.02 | F40: =IF(F12=0,0,-F16/F12) -> 0.02 | G40: =IF(G12=0,0,-G16/G12) -> 0.02 | H40: =IF(H12=0,0,-H16/H12) -> 0.02 | I40: =IF(I12=0,0,-I16/I12) -> 0.02 | J40: =IF(J12=0,0,-J16/J12) -> 0.02 | ... AL40: =IF(AL12=0,0,-AL16/AL12) -> 0.02
B41: · long-term storage (pessimistic) | C41: 0 | D41: 0 | E41: 0 | F41: 0 | G41: 0 | H41: 0 | I41: 0 | J41: 0 | K41: 0 | L41: 0 | M41: 0 | N41: 0 | O41: 0 | P41: 0 | Q41: 0 | R41: 0 | S41: 0 | T41: 0 | U41: 0 | V41: 0 | W41: 0 | X41: 0 | Y41: 0 | Z41: 0 | AA41: 0 | AB41: 0 | AC41: 0 | AD41: 0 | AE41: 0 | AF41: 0 | AG41: 0 | AH41: 0 | AI41: 0 | AJ41: 0 | AK41: 0 | AL41: 0
B42: · long-term storage (base) | C42: 0 | D42: 0 | E42: 0 | F42: 0 | G42: 0 | H42: 0 | I42: 0 | J42: 0 | K42: 0 | L42: 0 | M42: 0 | N42: 0 | O42: 0 | P42: 0 | Q42: 0 | R42: 0 | S42: 0 | T42: 0 | U42: 0 | V42: 0 | W42: 0 | X42: 0 | Y42: 0 | Z42: 0 | AA42: 0 | AB42: 0 | AC42: 0 | AD42: 0 | AE42: 0 | AF42: 0 | AG42: 0 | AH42: 0 | AI42: 0 | AJ42: 0 | AK42: 0 | AL42: 0
B43: · long-term storage (optimistic) | C43: 0 | D43: 0 | E43: 0 | F43: 0 | G43: 0 | H43: 0 | I43: 0 | J43: 0 | K43: 0 | L43: 0 | M43: 0 | N43: 0 | O43: 0 | P43: 0 | Q43: 0 | R43: 0 | S43: 0 | T43: 0 | U43: 0 | V43: 0 | W43: 0 | X43: 0 | Y43: 0 | Z43: 0 | AA43: 0 | AB43: 0 | AC43: 0 | AD43: 0 | AE43: 0 | AF43: 0 | AG43: 0 | AH43: 0 | AI43: 0 | AJ43: 0 | AK43: 0 | AL43: 0

Sheet PL Annual
B2: Made for Doraemon | F2: ="Currency: "&a_currency&" · switch on the Dashboard" -> Currency: JPY · switch on the Dashboard
B4: P&L — annual
B5: Yearly rollups of the live monthly P&L.
B7: P&L line | C7: Year 1 | D7: Year 2 | E7: Year 3 | F7: Total
B8: Units sold | C8: =SUM('PL Monthly'!C10:N10) -> 600 | D8: =SUM('PL Monthly'!O10:Z10) -> 1089 | E8: =SUM('PL Monthly'!AA10:AL10) -> 1317.69 | F8: =SUM('PL Monthly'!C10:AL10) -> 3006.69
B9: Gross sales | C9: =SUM('PL Monthly'!C12:N12) -> 2100000 | D9: =SUM('PL Monthly'!O12:Z12) -> 3811500 | E9: =SUM('PL Monthly'!AA12:AL12) -> 4611915 | F9: =SUM('PL Monthly'!C12:AL12) -> 10523415
B10: Output JCT | C10: =SUM('PL Monthly'!C13:N13) -> -190909.09 | D10: =SUM('PL Monthly'!O13:Z13) -> -346500 | E10: =SUM('PL Monthly'!AA13:AL13) -> -419265 | F10: =SUM('PL Monthly'!C13:AL13) -> -956674.09
B11: Amazon Points | C11: =SUM('PL Monthly'!C14:N14) -> -21000 | D11: =SUM('PL Monthly'!O14:Z14) -> -38115 | E11: =SUM('PL Monthly'!AA14:AL14) -> -46119.15 | F11: =SUM('PL Monthly'!C14:AL14) -> -105234.15
B12: Promotions & deals | C12: =SUM('PL Monthly'!C15:N15) -> -52500 | D12: =SUM('PL Monthly'!O15:Z15) -> -76230 | E12: =SUM('PL Monthly'!AA15:AL15) -> -92238.3 | F12: =SUM('PL Monthly'!C15:AL15) -> -220968.3
B13: Returns | C13: =SUM('PL Monthly'!C16:N16) -> -42000 | D13: =SUM('PL Monthly'!O16:Z16) -> -76230 | E13: =SUM('PL Monthly'!AA16:AL16) -> -92238.3 | F13: =SUM('PL Monthly'!C16:AL16) -> -210468.3
B14: Net revenue | C14: =SUM('PL Monthly'!C17:N17) -> 1793590.9 | D14: =SUM('PL Monthly'!O17:Z17) -> 3274425 | E14: =SUM('PL Monthly'!AA17:AL17) -> 3962054.2 | F14: =SUM('PL Monthly'!C17:AL17) -> 9030070.2
B15: Unit procurement cost | C15: =SUM('PL Monthly'!C18:N18) -> -945000 | D15: =SUM('PL Monthly'!O18:Z18) -> -1715175 | E15: =SUM('PL Monthly'!AA18:AL18) -> -2075361.8 | F15: =SUM('PL Monthly'!C18:AL18) -> -4735536.8
B16: Domestic logistics to FBA | C16: =SUM('PL Monthly'!C19:N19) -> -30000 | D16: =SUM('PL Monthly'!O19:Z19) -> -54450 | E16: =SUM('PL Monthly'!AA19:AL19) -> -65884.5 | F16: =SUM('PL Monthly'!C19:AL19) -> -150334.5
B17: Inspection / QC | C17: =SUM('PL Monthly'!C20:N20) -> 0 | D17: =SUM('PL Monthly'!O20:Z20) -> 0 | E17: =SUM('PL Monthly'!AA20:AL20) -> 0 | F17: =SUM('PL Monthly'!C20:AL20) -> 0
B18: Shrinkage & write-offs | C18: =SUM('PL Monthly'!C21:N21) -> -9750 | D18: =SUM('PL Monthly'!O21:Z21) -> -17696.25 | E18: =SUM('PL Monthly'!AA21:AL21) -> -21412.463 | F18: =SUM('PL Monthly'!C21:AL21) -> -48858.713
B19: Gross profit | C19: =SUM('PL Monthly'!C22:N22) -> 808840.91 | D19: =SUM('PL Monthly'!O22:Z22) -> 1487103.8 | E19: =SUM('PL Monthly'!AA22:AL22) -> 1799395.5 | F19: =SUM('PL Monthly'!C22:AL22) -> 4095340.2
B20: Referral fee | C20: =SUM('PL Monthly'!C23:N23) -> -218400 | D20: =SUM('PL Monthly'!O23:Z23) -> -396396 | E20: =SUM('PL Monthly'!AA23:AL23) -> -479639.16 | F20: =SUM('PL Monthly'!C23:AL23) -> -1094435.2
... B32: EBITDA | C32: =SUM('PL Monthly'!C35:N35) -> -1249418.4 | D32: =SUM('PL Monthly'!O35:Z35) -> -952566.69 | E32: =SUM('PL Monthly'!AA35:AL35) -> -813215.13 | F32: =SUM('PL Monthly'!C35:AL35) -> -3015200.2
B33: Operating metrics
B34: Advertising ROAS | C34: =IF(SUM('PL Monthly'!C29:N29)=0,0,-SUM('PL Monthly'!C12:N12)/SUM('PL Monthly'!C29:N29)) -> 4.7929454 | D34: =IF(SUM('PL Monthly'!O29:Z29)=0,0,-SUM('PL Monthly'!O12:Z12)/SUM('PL Monthly'!O29:Z29)) -> 8.3333333 | E34: =IF(SUM('PL Monthly'!AA29:AL29)=0,0,-SUM('PL Monthly'!AA12:AL12)/SUM('PL Monthly'!AA29:AL29)) -> 10 | F34: =IF(SUM('PL Monthly'!C29:AL29)=0,0,-SUM('PL Monthly'!C12:AL12)/SUM('PL Monthly'!C29:AL29)) -> 7.7565381
